Workbook

Sheet Firm_Info
A1: Ticker | B1: Company Name | C1: Role | D1: Pair_ID | E1: Sector | F1: Announcement_Date | G1: Post_Cutoff_Date | H1: First_Dividend_Amount
A2: META | B2: Meta Platforms | C2: Treated | D2: 1 | E2: Communication Services | F2: 45323 | G2: 45323 | H2: 0.5
A3: AMZN | B3: Amazon | C3: Control | D3: 1 | E3: Consumer Discretionary | F3: 45323
A4: GOOGL | B4: Alphabet | C4: Treated | D4: 2 | E4: Communication Services | F4: 45407 | G4: 45407 | H4: 0.2
A5: ADBE | B5: Adobe | C5: Control | D5: 2 | E5: Information Technology | F5: 45407
A6: CRM | B6: Salesforce | C6: Treated | D6: 3 | E6: Information Technology | F6: 45350 | G6: 45350 | H6: 0.4
A7: NOW | B7: ServiceNow | C7: Control | D7: 3 | E7: Information Technology | F7: 45350
A8: BKNG | B8: Booking Holdings | C8: Treated | D8: 4 | E8: Consumer Discretionary | F8: 45344 | G8: 45344 | H8: 8.75
A9: ABNB | B9: Airbnb | C9: Control | D9: 4 | E9: Consumer Discretionary | F9: 45344
A10: TMUS | B10: T-Mobile US | C10: Treated | D10: 5 | E10: Communication Services | F10: 45175 | G10: 45175 | H10: 0.65
A11: CHTR | B11: Charter Communications | C11: Control | D11: 5 | E11: Communication Services | F11: 45175
A12: SPY | B12: S&P 500 ETF | C12: Benchmark

Sheet Raw_Prices
A1: META | H1: AMZN | O1: GOOGL | V1: ADBE | AC1: CRM | AJ1: NOW | AQ1: BKNG | AX1: ABNB | BE1: TMUS | BL1: CHTR | BS1: SPY
A2: Date | B2: Open | C2: High | D2: Low | E2: Close | F2: Volume | H2: Date | I2: Open | J2: High | K2: Low | L2: Close | M2: Volume | O2: Date | P2: Open | Q2: High | R2: Low | S2: Close | T2: Volume | V2: Date | W2: Open | X2: High | Y2: Low | Z2: Close | AA2: Volume | AC2: Date | AD2: Open | AE2: High | AF2: Low | AG2: Close | AH2: Volume | AJ2: Date | AK2: Open | AL2: High | AM2: Low | AN2: Close | AO2: Volume | AQ2: Date | AR2: Open | AS2: High | AT2: Low | AU2: Close | AV2: Volume | AX2: Date | AY2: Open | AZ2: High | BA2: Low | BB2: Close | BC2: Volume | BE2: Date | BF2: Open | BG2: High | BH2: Low | BI2: Close | BJ2: Volume | BL2: Date | BM2: Open | BN2: High | BO2: Low | BP2: Close | BQ2: Volume | BS2: Date | BT2: Open | BU2: High | BV2: Low | BW2: Close | BX2: Volume
A3: 44929 | B3: 122.82 | C3: 126.37 | D3: 122.28 | E3: 124.74 | F3: 35528531 | H3: 44929 | I3: 85.46 | J3: 86.96 | K3: 84.205 | L3: 85.82 | M3: 76706040 | O3: 44929 | P3: 89.2614 | Q3: 90.7211 | R3: 88.2002 | S3: 88.798 | T3: 28233202 | V3: 44929 | W3: 340.16 | X3: 345.82 | Y3: 331.92 | Z3: 336.92 | AA3: 2229104 | AC3: 44929 | AD3: 135.19 | AE3: 136.95 | AF3: 133.03 | AG3: 134.78 | AH3: 8196354 | AJ3: 44929 | AK3: 79.016 | AL3: 79.73 | AM3: 76.13 | AN3: 77.1 | AO3: 5440380 | AQ3: 44929 | AR3: 80.0576 | AS3: 80.457 | AT3: 78.7516 | AU3: 79.7977 | AV3: 6799665 | AX3: 44929 | AY3: 87.385 | AZ3: 88.14 | BA3: 84.3 | BB3: 84.9 | BC3: 3901185 | BE3: 44929 | BF3: 139 | BG3: 140.09 | BH3: 136.26 | BI3: 139.04 | BJ3: 8245426 | BL3: 44929 | BM3: 342.06 | BN3: 345.53 | BO3: 337.18 | BP3: 341.58 | BQ3: 1524126 | BS3: 44929 | BT3: 372.699 | BU3: 374.698 | BV3: 366.359 | BW3: 369.257 | BX3: 77194556
A4: 44930 | B4: 127.38 | C4: 129.0498 | D4: 125.85 | E4: 127.37 | F4: 32397094 | H4: 44930 | I4: 86.55 | J4: 86.98 | K4: 83.36 | L4: 85.14 | M4: 68885123 | O4: 44930 | P4: 90.0236 | Q4: 90.3226 | R4: 86.9558 | S4: 87.7618 | T4: 34981128 | V4: 44930 | W4: 342.89 | X4: 345.6292 | Y4: 336.73 | Z4: 341.41 | AA4: 2186849 | AC4: 44930 | AD4: 141.22 | AE4: 141.85 | AF4: 137.615 | AG4: 139.59 | AH4: 14322576 | AJ4: 44930 | AK4: 78.19 | AL4: 79.412 | AM4: 76.948 | AN4: 78.77 | AO4: 7025085 | AQ4: 44930 | AR4: 81.2357 | AS4: 82.9933 | AT4: 80.7623 | AU4: 82.8694 | AV4: 9375602 | AX4: 44930 | AY4: 85.89 | AZ4: 88.84 | BA4: 84.79 | BB4: 88.72 | BC4: 4817088 | BE4: 44930 | BF4: 140.5 | BG4: 140.98 | BH4: 137.36 | BI4: 139.96 | BJ4: 6900798 | BL4: 44930 | BM4: 347.01 | BN4: 355.9257 | BO4: 345.21 | BP4: 354 | BQ4: 1643217 | BS4: 44930 | BT4: 371.546 | BU4: 374.164 | BV4: 368.462 | BW4: 372.108 | BX4: 88624980
A5: 44931 | B5: 126.125 | C5: 128.52 | D5: 124.54 | E5: 126.94 | F5: 25447099 | H5: 44931 | I5: 85.33 | J5: 85.42 | K5: 83.07 | L5: 83.12 | M5: 67930825 | O5: 44931 | P5: 87.154 | Q5: 87.2537 | R5: 85.5897 | S5: 85.8887 | T5: 27292957 | V5: 44931 | W5: 337.53 | X5: 337.55 | Y5: 328.16 | Z5: 328.44 | AA5: 2081625 | AC5: 44931 | AD5: 137.64 | AE5: 138.59 | AF5: 134.24 | AG5: 136.34 | AH5: 8493489 | AJ5: 44931 | AK5: 77.69 | AL5: 77.94 | AM5: 73.05 | AN5: 73.264 | AO5: 8950220 | AQ5: 44931 | AR5: 81.89 | AS5: 84.5591 | AT5: 81.89 | AU5: 84.2242 | AV5: 9576995 | AX5: 44931 | AY5: 88.48 | AZ5: 88.5 | BA5: 86.75 | BB5: 87.71 | BC5: 3419036 | BE5: 44931 | BF5: 140.63 | BG5: 145.1199 | BH5: 140.16 | BI5: 144.48 | BJ5: 9254901 | BL5: 44931 | BM5: 362.4 | BN5: 365.88 | BO5: 355.37 | BP5: 361.43 | BQ5: 1490586 | BS5: 44931 | BT5: 370.13 | BU5: 370.246 | BV5: 367.26 | BW5: 367.861 | BX5: 79380657
A6: 44932 | B6: 128.97 | C6: 130.33 | D6: 126.04 | E6: 130.02 | F6: 27584498 | H6: 44932 | I6: 83.03 | J6: 86.4 | K6: 81.43 | L6: 86.08 | M6: 83303361 | O6: 44932 | P6: 86.4765 | Q6: 87.3733 | R6: 84.5535 | S6: 87.0246 | T6: 41531507 | V6: 44932 | W6: 332.28 | X6: 334.88 | Y6: 322.44 | Z6: 332.75 | AA6: 2216579 | AC6: 44932 | AD6: 137.58 | AE6: 141.65 | AF6: 135.55 | AG6: 140.51 | AH6: 9145711 | AJ6: 44932 | AK6: 74.318 | AL6: 74.318 | AM6: 70.724 | AN6: 73.306 | AO6: 13383640 | AQ6: 44932 | AR6: 85.0166 | AS6: 86.0408 | AT6: 84.4685 | AU6: 85.5716 | AV6: 8923766 | AX6: 44932 | AY6: 88.52 | AZ6: 88.74 | BA6: 85.71 | BB6: 88.52 | BC6: 4348374 | BE6: 44932 | BF6: 145.79 | BG6: 149.47 | BH6: 145.79 | BI6: 148.57 | BJ6: 6539579 | BL6: 44932 | BM6: 367.07 | BN6: 370.29 | BO6: 360.79 | BP6: 367.73 | BQ6: 1086004 | BS6: 44932 | BT6: 370.993 | BU6: 377.431 | BV6: 367.893 | BW6: 376.297 | BX6: 107452126
A7: 44935 | B7: 131.16 | C7: 132.95 | D7: 129.28 | E7: 129.47 | F7: 26649145 | H7: 44935 | I7: 87.46 | J7: 89.48 | K7: 87.08 | L7: 87.36 | M7: 65266056 | O7: 44935 | P7: 88.0408 | Q7: 89.7248 | R7: 87.5427 | S7: 87.7021 | T7: 29109043 | V7: 44935 | W7: 338.9 | X7: 349.455 | Y7: 338.42 | Z7: 341.98 | AA7: 3133817 | AC7: 44935 | AD7: 142.59 | AE7: 149.2 | AF7: 142.59 | AG7: 147.1 | AH7: 13679737 | AJ7: 44935 | AK7: 74.776 | AL7: 78.598 | AM7: 74.638 | AN7: 75.712 | AO7: 10439070 | AQ7: 44935 | AR7: 86.19 | AS7: 87.2705 | AT7: 85.794 | AU7: 86.7165 | AV7: 6917985 | AX7: 44935 | AY7: 90.255 | AZ7: 92.05 | BA7: 88.88 | BB7: 89.24 | BC7: 4319380 | BE7: 44935 | BF7: 148.02 | BG7: 150.23 | BH7: 147.75 | BI7: 148.77 | BJ7: 4977094 | BL7: 44935 | BM7: 365 | BN7: 369.08 | BO7: 363.54 | BP7: 367.18 | BQ7: 1073518 | BS7: 44935 | BT7: 378.517 | BU7: 381.747 | BV7: 375.899 | BW7: 376.084 | BX7: 76294570
A8: 44936 | B8: 127.27 | C8: 133.44 | D8: 127.15 | E8: 132.99 | F8: 28684431 | H8: 44936 | I8: 87.57 | J8: 90.185 | K8: 87.29 | L8: 89.87 | M8: 67756601 | O8: 44936 | P8: 85.6694 | Q8: 88.3496 | R8: 85.52 | S8: 88.1006 | T8: 30578203 | V8: 44936 | W8: 337.65 | X8: 344.63 | Y8: 336.8 | Z8: 338.7 | AA8: 1670248 | AC8: 44936 | AD8: 145.81 | AE8: 149.28 | AF8: 145.6039 | AG8: 147.44 | AH8: 6527711 | AJ8: 44936 | AK8: 74.874 | AL8: 76.754 | AM8: 74.874 | AN8: 76.168 | AO8: 5322775 | AQ8: 44936 | AR8: 86.4082 | AS8: 87.2093 | AT8: 85.5746 | AU8: 87.2089 | AV8: 5518623 | AX8: 44936 | AY8: 88.86 | AZ8: 89.62 | BA8: 86.75 | BB8: 88.54 | BC8: 4165610 | BE8: 44936 | BF8: 148.97 | BG8: 149.9 | BH8: 147.74 | BI8: 149.56 | BJ8: 3779510 | BL8: 44936 | BM8: 367.18 | BN8: 374.64 | BO8: 366.69 | BP8: 374.64 | BQ8: 1115036 | BS8: 44936 | BT8: 375.492 | BU8: 378.789 | BV8: 374.542 | BW8: 378.721 | BX8: 67404673
A9: 44937 | B9: 130.96 | C9: 133.8494 | D9: 130.34 | E9: 132.89 | F9: 25423046 | H9: 44937 | I9: 90.93 | J9: 95.26 | K9: 90.93 | L9: 95.09 | M9: 103126183 | O9: 44937 | P9: 88.858 | Q9: 91.2692 | R9: 88.6886 | S9: 91.1895 | T9: 26959346 | V9: 44937 | W9: 337.39 | X9: 343.19 | Y9: 333.47 | Z9: 342.93 | AA9: 2344403 | AC9: 44937 | AD9: 145.28 | AE9: 147.04 | AF9: 143.56 | AG9: 144.9 | AH9: 13595042 | AJ9: 44937 | AK9: 76.964 | AL9: 78.784 | AM9: 76.642 | AN9: 78.756 | AO9: 6292020 | AQ9: 44937 | AR9: 87.3032 | AS9: 88.2032 | AT9: 86.9949 | AU9: 87.3605 | AV9: 7385355 | AX9: 44937 | AY9: 89 | AZ9: 94.83 | BA9: 88.864 | BB9: 94.44 | BC9: 7718901 | BE9: 44937 | BF9: 149.5 | BG9: 149.845 | BH9: 148.1223 | BI9: 148.8 | BJ9: 4451508 | BL9: 44937 | BM9: 377.3 | BN9: 379.685 | BO9: 372.22 | BP9: 378.43 | BQ9: 848692 | BS9: 44937 | BT9: 380.32 | BU9: 383.588 | BV9: 379.497 | BW9: 383.51 | BX9: 71037975
A10: 44938 | B10: 133.44 | C10: 137.6781 | D10: 131.76 | E10: 136.71 | F10: 30757732 | H10: 44938 | I10: 96.93 | J10: 97.19 | K10: 93.5 | L10: 95.27 | M10: 85254781 | O10: 44938 | P10: 91.1495 | Q10: 91.5382 | R10: 89.4258 | S10: 90.8008 | T10: 30367823 | V10: 44938 | W10: 344.165 | X10: 346.44 | Y10: 337.37 | Z10: 344.54 | AA10: 2121831 | AC10: 44938 | AD10: 147.84 | AE10: 149.82 | AF10: 143.94 | AG10: 149.6 | AH10: 11678023 | AJ10: 44938 | AK10: 81.966 | AL10: 84.168 | AM10: 79.169 | AN10: 82.652 | AO10: 11570055 | AQ10: 44938 | AR10: 87.3886 | AS10: 89.0431 | AT10: 86.9616 | AU10: 88.6155 | AV10: 7438810 | AX10: 44938 | AY10: 95.31 | AZ10: 98.95 | BA10: 94.02 | BB10: 98.49 | BC10: 7695221 | BE10: 44938 | BF10: 147.77 | BG10: 150.09 | BH10: 146.55 | BI10: 149.91 | BJ10: 4269378 | BL10: 44938 | BM10: 380.61 | BN10: 388.57 | BO10: 377.755 | BP10: 385.47 | BQ10: 1207742 | BS10: 44938 | BT10: 384.626 | BU10: 386.388 | BV10: 380.507 | BW10: 384.907 | BX10: 92980836
A11: 44939 | B11: 134.97 | C11: 137.39 | D11: 134.835 | E11: 136.98 | F11: 22423839 | H11: 44939 | I11: 94.18 | J11: 98.37 | K11: 94.12 | L11: 98.12 | M11: 85549432 | O11: 44939 | P11: 90.5219 | Q11: 91.857 | R11: 89.8044 | S11: 91.7873 | T11: 26424658 | V11: 44939 | W11: 340.25 | X11: 344.65 | Y11: 335.5 | Z11: 344.38 | AA11: 2582132 | AC11: 44939 | AD11: 146.2 | AE11: 149.96 | AF11: 146.0942 | AG11: 149.51 | AH11: 8378111 | AJ11: 44939 | AK11: 81.734 | AL11: 83.47 | AM11: 81.6111 | AN11: 82.978 | AO11: 5590965 | AQ11: 44939 | AR11: 87.3032 | AS11: 90.392 | AT11: 87.2564 | AU11: 90.3656 | AV11: 7402189 | AX11: 44939 | AY11: 97.5 | AZ11: 100.6999 | BA11: 97.42 | BB11: 100.37 | BC11: 6528993 | BE11: 44939 | BF11: 149.91 | BG11: 150.5683 | BH11: 148.26 | BI11: 149.68 | BJ11: 6543839 | BL11: 44939 | BM11: 383.97 | BN11: 389.96 | BO11: 383.67 | BP11: 388.47 | BQ11: 780923 | BS11: 44939 | BT11: 381.668 | BU11: 386.982 | BV11: 381.398 | BW11: 386.401 | BX11: 65904976
A12: 44943 | B12: 136.176 | C12: 136.75 | D12: 134.25 | E12: 135.36 | F12: 21147587 | H12: 44943 | I12: 98.68 | J12: 98.89 | K12: 95.73 | L12: 96.05 | M12: 72755001 | O12: 44943 | P12: 91.7275 | Q12: 91.9168 | R12: 89.7248 | S12: 90.9603 | T12: 32720610 | V12: 44943 | W12: 344.38 | X12: 350.786 | Y12: 341.97 | Z12: 344.38 | AA12: 2512729 | AC12: 44943 | AD12: 149.6 | AE12: 150.49 | AF12: 146.1001 | AG12: 148.47 | AH12: 9407610 | AJ12: 44943 | AK12: 83 | AL12: 83.884 | AM12: 81.59 | AN12: 83.648 | AO12: 6743650 | AQ12: 44943 | AR12: 90.2308 | AS12: 91.7395 | AT12: 90.2308 | AU12: 91.6487 | AV12: 8763095 | AX12: 44943 | AY12: 99.915 | AZ12: 102.735 | BA12: 99.1 | BB12: 101.27 | BC12: 5496249 | BE12: 44943 | BF12: 149.18 | BG12: 149.18 | BH12: 146.635 | BI12: 146.98 | BJ12: 5481985 | BL12: 44943 | BM12: 385.89 | BN12: 390.98 | BO12: 383.77 | BP12: 388.35 | BQ12: 907955 | BS12: 44943 | BT12: 386.383 | BU12: 388.078 | BV12: 385.005 | BW12: 385.691 | BX12: 64639915
A13: 44944 | B13: 135.81 | C13: 137.25 | D13: 132.8 | E13: 133.02 | F13: 20215486 | H13: 44944 | I13: 97.25 | J13: 99.32 | K13: 95.38 | L13: 95.46 | M13: 79570370 | O13: 44944 | P13: 91.8072 | Q13: 92.4647 | R13: 90.3126 | S13: 90.7908 | T13: 29222241 | V13: 44944 | W13: 345.01 | X13: 349.24 | Y13: 338.4 | Z13: 341.31 | AA13: 2080033 | AC13: 44944 | AD13: 148.86 | AE13: 149.54 | AF13: 145.29 | AG13: 145.45 | AH13: 7812580 | AJ13: 44944 | AK13: 84.158 | AL13: 86.3 | AM13: 82.928 | AN13: 83.24 | AO13: 8633290 | AQ13: 44944 | AR13: 92.6689 | AS13: 93.2469 | AT13: 90.0553 | AU13: 90.1736 | AV13: 7820459 | AX13: 44944 | AY13: 101.41 | AZ13: 103.8001 | BA13: 100.32 | BB13: 101.11 | BC13: 6062224 | BE13: 44944 | BF13: 146.13 | BG13: 147.74 | BH13: 145.5 | BI13: 145.9 | BJ13: 4543391 | BL13: 44944 | BM13: 386.3 | BN13: 390.975 | BO13: 381.25 | BP13: 381.86 | BQ13: 1166218 | BS13: 44944 | BT13: 386.895 | BU13: 387.972 | BV13: 379.399 | BW13: 379.603 | BX13: 102752079
A14: 44945 | B14: 132.49 | C14: 137.45 | D14: 132.14 | E14: 136.15 | F14: 28625232 | H14: 44945 | I14: 94.74 | J14: 95.44 | K14: 92.86 | L14: 93.68 | M14: 69002663 | O14: 44945 | P14: 90.3923 | Q14: 93.2669 | R14: 90.3026 | S14: 92.7138 | T14: 37134525 | V14: 44945 | W14: 340.56 | X14: 346.73 | Y14: 340.01 | Z14: 342.53 | AA14: 2466965 | AC14: 44945 | AD14: 143.52 | AE14: 146.68 | AF14: 143.16 | AG14: 146.41 | AH14: 7070135 | AJ14: 44945 | AK14: 83.204 | AL14: 86.8532 | AM14: 83.06 | AN14: 85.686 | AO14: 13394475 | AQ14: 44945 | AR14: 89.1348 | AS14: 91.1901 | AT14: 89.0707 | AU14: 90.9176 | AV14: 7239124 | AX14: 44945 | AY14: 99.84 | AZ14: 100.52 | BA14: 97.57 | BB14: 99.1 | BC14: 4996747 | BE14: 44945 | BF14: 145.18 | BG14: 145.67 | BH14: 143.66 | BI14: 145.14 | BJ14: 5345710 | BL14: 44945 | BM14: 379.09 | BN14: 385.01 | BO14: 373.85 | BP14: 384.2 | BQ14: 1317287 | BS14: 44945 | BT14: 377.538 | BU14: 379.207 | BV14: 375.502 | BW14: 376.84 | BX14: 89681892
... A626: 45838 | B626: 744.55 | C626: 747.9 | D626: 734.25 | E626: 738.09 | F626: 15402105 | H626: 45838 | I626: 223.52 | J626: 223.82 | K626: 219.12 | L626: 219.39 | M626: 58887780 | O626: 45838 | P626: 180.78 | Q626: 181.23 | R626: 174.58 | S626: 176.23 | T626: 63378856 | V626: 45838 | W626: 387.3 | X626: 390.98 | Y626: 384.63 | Z626: 386.88 | AA626: 4645498 | AC626: 45838 | AD626: 274.46 | AE626: 276.38 | AF626: 270.4 | AG626: 272.69 | AH626: 8541909 | AJ626: 45838 | AK626: 205.298 | AL626: 207.274 | AM626: 203.689 | AN626: 205.616 | AO626: 5046545 | AQ626: 45838 | AR626: 226.82 | AS626: 230.593 | AT626: 226.32 | AU626: 230.206 | AV626: 7236536 | AX626: 45838 | AY626: 135.06 | AZ626: 135.06 | BA626: 131.945 | BB626: 132.34 | BC626: 3666177 | BE626: 45838 | BF626: 234.49 | BG626: 238.62 | BH626: 234.2303 | BI626: 238.26 | BJ626: 5118676 | BL626: 45838 | BM626: 402.5 | BN626: 410.38 | BO626: 402.25 | BP626: 408.81 | BQ626: 1281858 | BS626: 45838 | BT626: 617.38 | BU626: 619.22 | BV626: 615.04 | BW626: 617.85 | BX626: 92502541

Sheet Panel_Data
A1: Ticker | B1: Date | C1: Close | D1: Return | E1: Treat | F1: Pair_ID | G1: Post | H1: Treat_x_Post | I1: RelTD
A2: META | B2: =Raw_Prices!A3 -> 44929 | C2: =Raw_Prices!E3 -> 124.74 | E2: =IF(_xlfn.XLOOKUP($A2,Firm_Info!$A$2:$A$12,Firm_Info!$C$2:$C$12)="Treated",1,IF(_xlfn.XLOOKUP($A2,Firm_Info!$A$2:$A$12,Firm_Info!$C$2:$C$12)="Control",0,"")) -> 1 | F2: =IFERROR(_xlfn.XLOOKUP($A2,Firm_Info!$A$2:$A$11,Firm_Info!$D$2:$D$11),"") -> 1 | G2: =IF($F2="","",IF($B2>=SUMIFS(Firm_Info!$F$2:$F$11,Firm_Info!$D$2:$D$11,$F2,Firm_Info!$C$2:$C$11,"Treated"),1,0)) -> 0 | H2: =IF($F2="","",$E2*$G2) -> 0 | I2: =IF($F2="","",MOD(ROW()-2,624)-INDEX(Parallel_Trends!$F$5:$F$14,MATCH($A2,Parallel_Trends!$A$5:$A$14,0))) -> -271
A3: META | B3: =Raw_Prices!A4 -> 44930 | C3: =Raw_Prices!E4 -> 127.37 | D3: =C3/C2-1 -> 0.021083854 | E3: =IF(_xlfn.XLOOKUP($A3,Firm_Info!$A$2:$A$12,Firm_Info!$C$2:$C$12)="Treated",1,IF(_xlfn.XLOOKUP($A3,Firm_Info!$A$2:$A$12,Firm_Info!$C$2:$C$12)="Control",0,"")) -> 1 | F3: =IFERROR(_xlfn.XLOOKUP($A3,Firm_Info!$A$2:$A$11,Firm_Info!$D$2:$D$11),"") -> 1 | G3: =IF($F3="","",IF($B3>=SUMIFS(Firm_Info!$F$2:$F$11,Firm_Info!$D$2:$D$11,$F3,Firm_Info!$C$2:$C$11,"Treated"),1,0)) -> 0 | H3: =IF($F3="","",$E3*$G3) -> 0 | I3: =IF($F3="","",MOD(ROW()-2,624)-INDEX(Parallel_Trends!$F$5:$F$14,MATCH($A3,Parallel_Trends!$A$5:$A$14,0))) -> -270
A4: META | B4: =Raw_Prices!A5 -> 44931 | C4: =Raw_Prices!E5 -> 126.94 | D4: =C4/C3-1 -> -0.0033759912 | E4: =IF(_xlfn.XLOOKUP($A4,Firm_Info!$A$2:$A$12,Firm_Info!$C$2:$C$12)="Treated",1,IF(_xlfn.XLOOKUP($A4,Firm_Info!$A$2:$A$12,Firm_Info!$C$2:$C$12)="Control",0,"")) -> 1 | F4: =IFERROR(_xlfn.XLOOKUP($A4,Firm_Info!$A$2:$A$11,Firm_Info!$D$2:$D$11),"") -> 1 | G4: =IF($F4="","",IF($B4>=SUMIFS(Firm_Info!$F$2:$F$11,Firm_Info!$D$2:$D$11,$F4,Firm_Info!$C$2:$C$11,"Treated"),1,0)) -> 0 | H4: =IF($F4="","",$E4*$G4) -> 0 | I4: =IF($F4="","",MOD(ROW()-2,624)-INDEX(Parallel_Trends!$F$5:$F$14,MATCH($A4,Parallel_Trends!$A$5:$A$14,0))) -> -269
A5: META | B5: =Raw_Prices!A6 -> 44932 | C5: =Raw_Prices!E6 -> 130.02 | D5: =C5/C4-1 -> 0.024263432 | E5: =IF(_xlfn.XLOOKUP($A5,Firm_Info!$A$2:$A$12,Firm_Info!$C$2:$C$12)="Treated",1,IF(_xlfn.XLOOKUP($A5,Firm_Info!$A$2:$A$12,Firm_Info!$C$2:$C$12)="Control",0,"")) -> 1 | F5: =IFERROR(_xlfn.XLOOKUP($A5,Firm_Info!$A$2:$A$11,Firm_Info!$D$2:$D$11),"") -> 1 | G5: =IF($F5="","",IF($B5>=SUMIFS(Firm_Info!$F$2:$F$11,Firm_Info!$D$2:$D$11,$F5,Firm_Info!$C$2:$C$11,"Treated"),1,0)) -> 0 | H5: =IF($F5="","",$E5*$G5) -> 0 | I5: =IF($F5="","",MOD(ROW()-2,624)-INDEX(Parallel_Trends!$F$5:$F$14,MATCH($A5,Parallel_Trends!$A$5:$A$14,0))) -> -268
A6: META | B6: =Raw_Prices!A7 -> 44935 | C6: =Raw_Prices!E7 -> 129.47 | D6: =C6/C5-1 -> -0.0042301184 | E6: =IF(_xlfn.XLOOKUP($A6,Firm_Info!$A$2:$A$12,Firm_Info!$C$2:$C$12)="Treated",1,IF(_xlfn.XLOOKUP($A6,Firm_Info!$A$2:$A$12,Firm_Info!$C$2:$C$12)="Control",0,"")) -> 1 | F6: =IFERROR(_xlfn.XLOOKUP($A6,Firm_Info!$A$2:$A$11,Firm_Info!$D$2:$D$11),"") -> 1 | G6: =IF($F6="","",IF($B6>=SUMIFS(Firm_Info!$F$2:$F$11,Firm_Info!$D$2:$D$11,$F6,Firm_Info!$C$2:$C$11,"Treated"),1,0)) -> 0 | H6: =IF($F6="","",$E6*$G6) -> 0 | I6: =IF($F6="","",MOD(ROW()-2,624)-INDEX(Parallel_Trends!$F$5:$F$14,MATCH($A6,Parallel_Trends!$A$5:$A$14,0))) -> -267
A7: META | B7: =Raw_Prices!A8 -> 44936 | C7: =Raw_Prices!E8 -> 132.99 | D7: =C7/C6-1 -> 0.027187766 | E7: =IF(_xlfn.XLOOKUP($A7,Firm_Info!$A$2:$A$12,Firm_Info!$C$2:$C$12)="Treated",1,IF(_xlfn.XLOOKUP($A7,Firm_Info!$A$2:$A$12,Firm_Info!$C$2:$C$12)="Control",0,"")) -> 1 | F7: =IFERROR(_xlfn.XLOOKUP($A7,Firm_Info!$A$2:$A$11,Firm_Info!$D$2:$D$11),"") -> 1 | G7: =IF($F7="","",IF($B7>=SUMIFS(Firm_Info!$F$2:$F$11,Firm_Info!$D$2:$D$11,$F7,Firm_Info!$C$2:$C$11,"Treated"),1,0)) -> 0 | H7: =IF($F7="","",$E7*$G7) -> 0 | I7: =IF($F7="","",MOD(ROW()-2,624)-INDEX(Parallel_Trends!$F$5:$F$14,MATCH($A7,Parallel_Trends!$A$5:$A$14,0))) -> -266
A8: META | B8: =Raw_Prices!A9 -> 44937 | C8: =Raw_Prices!E9 -> 132.89 | D8: =C8/C7-1 -> -0.00075193624 | E8: =IF(_xlfn.XLOOKUP($A8,Firm_Info!$A$2:$A$12,Firm_Info!$C$2:$C$12)="Treated",1,IF(_xlfn.XLOOKUP($A8,Firm_Info!$A$2:$A$12,Firm_Info!$C$2:$C$12)="Control",0,"")) -> 1 | F8: =IFERROR(_xlfn.XLOOKUP($A8,Firm_Info!$A$2:$A$11,Firm_Info!$D$2:$D$11),"") -> 1 | G8: =IF($F8="","",IF($B8>=SUMIFS(Firm_Info!$F$2:$F$11,Firm_Info!$D$2:$D$11,$F8,Firm_Info!$C$2:$C$11,"Treated"),1,0)) -> 0 | H8: =IF($F8="","",$E8*$G8) -> 0 | I8: =IF($F8="","",MOD(ROW()-2,624)-INDEX(Parallel_Trends!$F$5:$F$14,MATCH($A8,Parallel_Trends!$A$5:$A$14,0))) -> -265
A9: META | B9: =Raw_Prices!A10 -> 44938 | C9: =Raw_Prices!E10 -> 136.71 | D9: =C9/C8-1 -> 0.028745579 | E9: =IF(_xlfn.XLOOKUP($A9,Firm_Info!$A$2:$A$12,Firm_Info!$C$2:$C$12)="Treated",1,IF(_xlfn.XLOOKUP($A9,Firm_Info!$A$2:$A$12,Firm_Info!$C$2:$C$12)="Control",0,"")) -> 1 | F9: =IFERROR(_xlfn.XLOOKUP($A9,Firm_Info!$A$2:$A$11,Firm_Info!$D$2:$D$11),"") -> 1 | G9: =IF($F9="","",IF($B9>=SUMIFS(Firm_Info!$F$2:$F$11,Firm_Info!$D$2:$D$11,$F9,Firm_Info!$C$2:$C$11,"Treated"),1,0)) -> 0 | H9: =IF($F9="","",$E9*$G9) -> 0 | I9: =IF($F9="","",MOD(ROW()-2,624)-INDEX(Parallel_Trends!$F$5:$F$14,MATCH($A9,Parallel_Trends!$A$5:$A$14,0))) -> -264
A10: META | B10: =Raw_Prices!A11 -> 44939 | C10: =Raw_Prices!E11 -> 136.98 | D10: =C10/C9-1 -> 0.0019749835 | E10: =IF(_xlfn.XLOOKUP($A10,Firm_Info!$A$2:$A$12,Firm_Info!$C$2:$C$12)="Treated",1,IF(_xlfn.XLOOKUP($A10,Firm_Info!$A$2:$A$12,Firm_Info!$C$2:$C$12)="Control",0,"")) -> 1 | F10: =IFERROR(_xlfn.XLOOKUP($A10,Firm_Info!$A$2:$A$11,Firm_Info!$D$2:$D$11),"") -> 1 | G10: =IF($F10="","",IF($B10>=SUMIFS(Firm_Info!$F$2:$F$11,Firm_Info!$D$2:$D$11,$F10,Firm_Info!$C$2:$C$11,"Treated"),1,0)) -> 0 | H10: =IF($F10="","",$E10*$G10) -> 0 | I10: =IF($F10="","",MOD(ROW()-2,624)-INDEX(Parallel_Trends!$F$5:$F$14,MATCH($A10,Parallel_Trends!$A$5:$A$14,0))) -> -263
A11: META | B11: =Raw_Prices!A12 -> 44943 | C11: =Raw_Prices!E12 -> 135.36 | D11: =C11/C10-1 -> -0.011826544 | E11: =IF(_xlfn.XLOOKUP($A11,Firm_Info!$A$2:$A$12,Firm_Info!$C$2:$C$12)="Treated",1,IF(_xlfn.XLOOKUP($A11,Firm_Info!$A$2:$A$12,Firm_Info!$C$2:$C$12)="Control",0,"")) -> 1 | F11: =IFERROR(_xlfn.XLOOKUP($A11,Firm_Info!$A$2:$A$11,Firm_Info!$D$2:$D$11),"") -> 1 | G11: =IF($F11="","",IF($B11>=SUMIFS(Firm_Info!$F$2:$F$11,Firm_Info!$D$2:$D$11,$F11,Firm_Info!$C$2:$C$11,"Treated"),1,0)) -> 0 | H11: =IF($F11="","",$E11*$G11) -> 0 | I11: =IF($F11="","",MOD(ROW()-2,624)-INDEX(Parallel_Trends!$F$5:$F$14,MATCH($A11,Parallel_Trends!$A$5:$A$14,0))) -> -262
A12: META | B12: =Raw_Prices!A13 -> 44944 | C12: =Raw_Prices!E13 -> 133.02 | D12: =C12/C11-1 -> -0.017287234 | E12: =IF(_xlfn.XLOOKUP($A12,Firm_Info!$A$2:$A$12,Firm_Info!$C$2:$C$12)="Treated",1,IF(_xlfn.XLOOKUP($A12,Firm_Info!$A$2:$A$12,Firm_Info!$C$2:$C$12)="Control",0,"")) -> 1 | F12: =IFERROR(_xlfn.XLOOKUP($A12,Firm_Info!$A$2:$A$11,Firm_Info!$D$2:$D$11),"") -> 1 | G12: =IF($F12="","",IF($B12>=SUMIFS(Firm_Info!$F$2:$F$11,Firm_Info!$D$2:$D$11,$F12,Firm_Info!$C$2:$C$11,"Treated"),1,0)) -> 0 | H12: =IF($F12="","",$E12*$G12) -> 0 | I12: =IF($F12="","",MOD(ROW()-2,624)-INDEX(Parallel_Trends!$F$5:$F$14,MATCH($A12,Parallel_Trends!$A$5:$A$14,0))) -> -261
A13: META | B13: =Raw_Prices!A14 -> 44945 | C13: =Raw_Prices!E14 -> 136.15 | D13: =C13/C12-1 -> 0.023530296 | E13: =IF(_xlfn.XLOOKUP($A13,Firm_Info!$A$2:$A$12,Firm_Info!$C$2:$C$12)="Treated",1,IF(_xlfn.XLOOKUP($A13,Firm_Info!$A$2:$A$12,Firm_Info!$C$2:$C$12)="Control",0,"")) -> 1 | F13: =IFERROR(_xlfn.XLOOKUP($A13,Firm_Info!$A$2:$A$11,Firm_Info!$D$2:$D$11),"") -> 1 | G13: =IF($F13="","",IF($B13>=SUMIFS(Firm_Info!$F$2:$F$11,Firm_Info!$D$2:$D$11,$F13,Firm_Info!$C$2:$C$11,"Treated"),1,0)) -> 0 | H13: =IF($F13="","",$E13*$G13) -> 0 | I13: =IF($F13="","",MOD(ROW()-2,624)-INDEX(Parallel_Trends!$F$5:$F$14,MATCH($A13,Parallel_Trends!$A$5:$A$14,0))) -> -260
A14: META | B14: =Raw_Prices!A15 -> 44946 | C14: =Raw_Prices!E15 -> 139.37 | D14: =C14/C13-1 -> 0.023650386 | E14: =IF(_xlfn.XLOOKUP($A14,Firm_Info!$A$2:$A$12,Firm_Info!$C$2:$C$12)="Treated",1,IF(_xlfn.XLOOKUP($A14,Firm_Info!$A$2:$A$12,Firm_Info!$C$2:$C$12)="Control",0,"")) -> 1 | F14: =IFERROR(_xlfn.XLOOKUP($A14,Firm_Info!$A$2:$A$11,Firm_Info!$D$2:$D$11),"") -> 1 | G14: =IF($F14="","",IF($B14>=SUMIFS(Firm_Info!$F$2:$F$11,Firm_Info!$D$2:$D$11,$F14,Firm_Info!$C$2:$C$11,"Treated"),1,0)) -> 0 | H14: =IF($F14="","",$E14*$G14) -> 0 | I14: =IF($F14="","",MOD(ROW()-2,624)-INDEX(Parallel_Trends!$F$5:$F$14,MATCH($A14,Parallel_Trends!$A$5:$A$14,0))) -> -259
... A625: META | B625: =Raw_Prices!A626 -> 45838 | C625: =Raw_Prices!E626 -> 738.09 | D625: =C625/C624-1 -> 0.0060793588 | E625: =IF(_xlfn.XLOOKUP($A625,Firm_Info!$A$2:$A$12,Firm_Info!$C$2:$C$12)="Treated",1,IF(_xlfn.XLOOKUP($A625,Firm_Info!$A$2:$A$12,Firm_Info!$C$2:$C$12)="Control",0,"")) -> 1 | F625: =IFERROR(_xlfn.XLOOKUP($A625,Firm_Info!$A$2:$A$11,Firm_Info!$D$2:$D$11),"") -> 1 | G625: =IF($F625="","",IF($B625>=SUMIFS(Firm_Info!$F$2:$F$11,Firm_Info!$D$2:$D$11,$F625,Firm_Info!$C$2:$C$11,"Treated"),1,0)) -> 1 | H625: =IF($F625="","",$E625*$G625) -> 1 | I625: =IF($F625="","",MOD(ROW()-2,624)-INDEX(Parallel_Trends!$F$5:$F$14,MATCH($A625,Parallel_Trends!$A$5:$A$14,0))) -> 352
A626: AMZN | B626: =Raw_Prices!H3 -> 44929 | C626: =Raw_Prices!L3 -> 85.82 | E626: =IF(_xlfn.XLOOKUP($A626,Firm_Info!$A$2:$A$12,Firm_Info!$C$2:$C$12)="Treated",1,IF(_xlfn.XLOOKUP($A626,Firm_Info!$A$2:$A$12,Firm_Info!$C$2:$C$12)="Control",0,"")) -> 0 | F626: =IFERROR(_xlfn.XLOOKUP($A626,Firm_Info!$A$2:$A$11,Firm_Info!$D$2:$D$11),"") -> 1 | G626: =IF($F626="","",IF($B626>=SUMIFS(Firm_Info!$F$2:$F$11,Firm_Info!$D$2:$D$11,$F626,Firm_Info!$C$2:$C$11,"Treated"),1,0)) -> 0 | H626: =IF($F626="","",$E626*$G626) -> 0 | I626: =IF($F626="","",MOD(ROW()-2,624)-INDEX(Parallel_Trends!$F$5:$F$14,MATCH($A626,Parallel_Trends!$A$5:$A$14,0))) -> -271
A627: AMZN | B627: =Raw_Prices!H4 -> 44930 | C627: =Raw_Prices!L4 -> 85.14 | D627: =C627/C626-1 -> -0.0079235609 | E627: =IF(_xlfn.XLOOKUP($A627,Firm_Info!$A$2:$A$12,Firm_Info!$C$2:$C$12)="Treated",1,IF(_xlfn.XLOOKUP($A627,Firm_Info!$A$2:$A$12,Firm_Info!$C$2:$C$12)="Control",0,"")) -> 0 | F627: =IFERROR(_xlfn.XLOOKUP($A627,Firm_Info!$A$2:$A$11,Firm_Info!$D$2:$D$11),"") -> 1 | G627: =IF($F627="","",IF($B627>=SUMIFS(Firm_Info!$F$2:$F$11,Firm_Info!$D$2:$D$11,$F627,Firm_Info!$C$2:$C$11,"Treated"),1,0)) -> 0 | H627: =IF($F627="","",$E627*$G627) -> 0 | I627: =IF($F627="","",MOD(ROW()-2,624)-INDEX(Parallel_Trends!$F$5:$F$14,MATCH($A627,Parallel_Trends!$A$5:$A$14,0))) -> -270
A628: AMZN | B628: =Raw_Prices!H5 -> 44931 | C628: =Raw_Prices!L5 -> 83.12 | D628: =C628/C627-1 -> -0.023725628 | E628: =IF(_xlfn.XLOOKUP($A628,Firm_Info!$A$2:$A$12,Firm_Info!$C$2:$C$12)="Treated",1,IF(_xlfn.XLOOKUP($A628,Firm_Info!$A$2:$A$12,Firm_Info!$C$2:$C$12)="Control",0,"")) -> 0 | F628: =IFERROR(_xlfn.XLOOKUP($A628,Firm_Info!$A$2:$A$11,Firm_Info!$D$2:$D$11),"") -> 1 | G628: =IF($F628="","",IF($B628>=SUMIFS(Firm_Info!$F$2:$F$11,Firm_Info!$D$2:$D$11,$F628,Firm_Info!$C$2:$C$11,"Treated"),1,0)) -> 0 | H628: =IF($F628="","",$E628*$G628) -> 0 | I628: =IF($F628="","",MOD(ROW()-2,624)-INDEX(Parallel_Trends!$F$5:$F$14,MATCH($A628,Parallel_Trends!$A$5:$A$14,0))) -> -269
A629: AMZN | B629: =Raw_Prices!H6 -> 44932 | C629: =Raw_Prices!L6 -> 86.08 | D629: =C629/C628-1 -> 0.035611165 | E629: =IF(_xlfn.XLOOKUP($A629,Firm_Info!$A$2:$A$12,Firm_Info!$C$2:$C$12)="Treated",1,IF(_xlfn.XLOOKUP($A629,Firm_Info!$A$2:$A$12,Firm_Info!$C$2:$C$12)="Control",0,"")) -> 0 | F629: =IFERROR(_xlfn.XLOOKUP($A629,Firm_Info!$A$2:$A$11,Firm_Info!$D$2:$D$11),"") -> 1 | G629: =IF($F629="","",IF($B629>=SUMIFS(Firm_Info!$F$2:$F$11,Firm_Info!$D$2:$D$11,$F629,Firm_Info!$C$2:$C$11,"Treated"),1,0)) -> 0 | H629: =IF($F629="","",$E629*$G629) -> 0 | I629: =IF($F629="","",MOD(ROW()-2,624)-INDEX(Parallel_Trends!$F$5:$F$14,MATCH($A629,Parallel_Trends!$A$5:$A$14,0))) -> -268
A630: AMZN | B630: =Raw_Prices!H7 -> 44935 | C630: =Raw_Prices!L7 -> 87.36 | D630: =C630/C629-1 -> 0.014869888 | E630: =IF(_xlfn.XLOOKUP($A630,Firm_Info!$A$2:$A$12,Firm_Info!$C$2:$C$12)="Treated",1,IF(_xlfn.XLOOKUP($A630,Firm_Info!$A$2:$A$12,Firm_Info!$C$2:$C$12)="Control",0,"")) -> 0 | F630: =IFERROR(_xlfn.XLOOKUP($A630,Firm_Info!$A$2:$A$11,Firm_Info!$D$2:$D$11),"") -> 1 | G630: =IF($F630="","",IF($B630>=SUMIFS(Firm_Info!$F$2:$F$11,Firm_Info!$D$2:$D$11,$F630,Firm_Info!$C$2:$C$11,"Treated"),1,0)) -> 0 | H630: =IF($F630="","",$E630*$G630) -> 0 | I630: =IF($F630="","",MOD(ROW()-2,624)-INDEX(Parallel_Trends!$F$5:$F$14,MATCH($A630,Parallel_Trends!$A$5:$A$14,0))) -> -267
A631: AMZN | B631: =Raw_Prices!H8 -> 44936 | C631: =Raw_Prices!L8 -> 89.87 | D631: =C631/C630-1 -> 0.028731685 | E631: =IF(_xlfn.XLOOKUP($A631,Firm_Info!$A$2:$A$12,Firm_Info!$C$2:$C$12)="Treated",1,IF(_xlfn.XLOOKUP($A631,Firm_Info!$A$2:$A$12,Firm_Info!$C$2:$C$12)="Control",0,"")) -> 0 | F631: =IFERROR(_xlfn.XLOOKUP($A631,Firm_Info!$A$2:$A$11,Firm_Info!$D$2:$D$11),"") -> 1 | G631: =IF($F631="","",IF($B631>=SUMIFS(Firm_Info!$F$2:$F$11,Firm_Info!$D$2:$D$11,$F631,Firm_Info!$C$2:$C$11,"Treated"),1,0)) -> 0 | H631: =IF($F631="","",$E631*$G631) -> 0 | I631: =IF($F631="","",MOD(ROW()-2,624)-INDEX(Parallel_Trends!$F$5:$F$14,MATCH($A631,Parallel_Trends!$A$5:$A$14,0))) -> -266
A632: AMZN | B632: =Raw_Prices!H9 -> 44937 | C632: =Raw_Prices!L9 -> 95.09 | D632: =C632/C631-1 -> 0.058083899 | E632: =IF(_xlfn.XLOOKUP($A632,Firm_Info!$A$2:$A$12,Firm_Info!$C$2:$C$12)="Treated",1,IF(_xlfn.XLOOKUP($A632,Firm_Info!$A$2:$A$12,Firm_Info!$C$2:$C$12)="Control",0,"")) -> 0 | F632: =IFERROR(_xlfn.XLOOKUP($A632,Firm_Info!$A$2:$A$11,Firm_Info!$D$2:$D$11),"") -> 1 | G632: =IF($F632="","",IF($B632>=SUMIFS(Firm_Info!$F$2:$F$11,Firm_Info!$D$2:$D$11,$F632,Firm_Info!$C$2:$C$11,"Treated"),1,0)) -> 0 | H632: =IF($F632="","",$E632*$G632) -> 0 | I632: =IF($F632="","",MOD(ROW()-2,624)-INDEX(Parallel_Trends!$F$5:$F$14,MATCH($A632,Parallel_Trends!$A$5:$A$14,0))) -> -265
A633: AMZN | B633: =Raw_Prices!H10 -> 44938 | C633: =Raw_Prices!L10 -> 95.27 | D633: =C633/C632-1 -> 0.0018929435 | E633: =IF(_xlfn.XLOOKUP($A633,Firm_Info!$A$2:$A$12,Firm_Info!$C$2:$C$12)="Treated",1,IF(_xlfn.XLOOKUP($A633,Firm_Info!$A$2:$A$12,Firm_Info!$C$2:$C$12)="Control",0,"")) -> 0 | F633: =IFERROR(_xlfn.XLOOKUP($A633,Firm_Info!$A$2:$A$11,Firm_Info!$D$2:$D$11),"") -> 1 | G633: =IF($F633="","",IF($B633>=SUMIFS(Firm_Info!$F$2:$F$11,Firm_Info!$D$2:$D$11,$F633,Firm_Info!$C$2:$C$11,"Treated"),1,0)) -> 0 | H633: =IF($F633="","",$E633*$G633) -> 0 | I633: =IF($F633="","",MOD(ROW()-2,624)-INDEX(Parallel_Trends!$F$5:$F$14,MATCH($A633,Parallel_Trends!$A$5:$A$14,0))) -> -264
A634: AMZN | B634: =Raw_Prices!H11 -> 44939 | C634: =Raw_Prices!L11 -> 98.12 | D634: =C634/C633-1 -> 0.029914978 | E634: =IF(_xlfn.XLOOKUP($A634,Firm_Info!$A$2:$A$12,Firm_Info!$C$2:$C$12)="Treated",1,IF(_xlfn.XLOOKUP($A634,Firm_Info!$A$2:$A$12,Firm_Info!$C$2:$C$12)="Control",0,"")) -> 0 | F634: =IFERROR(_xlfn.XLOOKUP($A634,Firm_Info!$A$2:$A$11,Firm_Info!$D$2:$D$11),"") -> 1 | G634: =IF($F634="","",IF($B634>=SUMIFS(Firm_Info!$F$2:$F$11,Firm_Info!$D$2:$D$11,$F634,Firm_Info!$C$2:$C$11,"Treated"),1,0)) -> 0 | H634: =IF($F634="","",$E634*$G634) -> 0 | I634: =IF($F634="","",MOD(ROW()-2,624)-INDEX(Parallel_Trends!$F$5:$F$14,MATCH($A634,Parallel_Trends!$A$5:$A$14,0))) -> -263
A635: AMZN | B635: =Raw_Prices!H12 -> 44943 | C635: =Raw_Prices!L12 -> 96.05 | D635: =C635/C634-1 -> -0.021096616 | E635: =IF(_xlfn.XLOOKUP($A635,Firm_Info!$A$2:$A$12,Firm_Info!$C$2:$C$12)="Treated",1,IF(_xlfn.XLOOKUP($A635,Firm_Info!$A$2:$A$12,Firm_Info!$C$2:$C$12)="Control",0,"")) -> 0 | F635: =IFERROR(_xlfn.XLOOKUP($A635,Firm_Info!$A$2:$A$11,Firm_Info!$D$2:$D$11),"") -> 1 | G635: =IF($F635="","",IF($B635>=SUMIFS(Firm_Info!$F$2:$F$11,Firm_Info!$D$2:$D$11,$F635,Firm_Info!$C$2:$C$11,"Treated"),1,0)) -> 0 | H635: =IF($F635="","",$E635*$G635) -> 0 | I635: =IF($F635="","",MOD(ROW()-2,624)-INDEX(Parallel_Trends!$F$5:$F$14,MATCH($A635,Parallel_Trends!$A$5:$A$14,0))) -> -262
A636: AMZN | B636: =Raw_Prices!H13 -> 44944 | C636: =Raw_Prices!L13 -> 95.46 | D636: =C636/C635-1 -> -0.006142634 | E636: =IF(_xlfn.XLOOKUP($A636,Firm_Info!$A$2:$A$12,Firm_Info!$C$2:$C$12)="Treated",1,IF(_xlfn.XLOOKUP($A636,Firm_Info!$A$2:$A$12,Firm_Info!$C$2:$C$12)="Control",0,"")) -> 0 | F636: =IFERROR(_xlfn.XLOOKUP($A636,Firm_Info!$A$2:$A$11,Firm_Info!$D$2:$D$11),"") -> 1 | G636: =IF($F636="","",IF($B636>=SUMIFS(Firm_Info!$F$2:$F$11,Firm_Info!$D$2:$D$11,$F636,Firm_Info!$C$2:$C$11,"Treated"),1,0)) -> 0 | H636: =IF($F636="","",$E636*$G636) -> 0 | I636: =IF($F636="","",MOD(ROW()-2,624)-INDEX(Parallel_Trends!$F$5:$F$14,MATCH($A636,Parallel_Trends!$A$5:$A$14,0))) -> -261
A637: AMZN | B637: =Raw_Prices!H14 -> 44945 | C637: =Raw_Prices!L14 -> 93.68 | D637: =C637/C636-1 -> -0.018646554 | E637: =IF(_xlfn.XLOOKUP($A637,Firm_Info!$A$2:$A$12,Firm_Info!$C$2:$C$12)="Treated",1,IF(_xlfn.XLOOKUP($A637,Firm_Info!$A$2:$A$12,Firm_Info!$C$2:$C$12)="Control",0,"")) -> 0 | F637: =IFERROR(_xlfn.XLOOKUP($A637,Firm_Info!$A$2:$A$11,Firm_Info!$D$2:$D$11),"") -> 1 | G637: =IF($F637="","",IF($B637>=SUMIFS(Firm_Info!$F$2:$F$11,Firm_Info!$D$2:$D$11,$F637,Firm_Info!$C$2:$C$11,"Treated"),1,0)) -> 0 | H637: =IF($F637="","",$E637*$G637) -> 0 | I637: =IF($F637="","",MOD(ROW()-2,624)-INDEX(Parallel_Trends!$F$5:$F$14,MATCH($A637,Parallel_Trends!$A$5:$A$14,0))) -> -260
A638: AMZN | B638: =Raw_Prices!H15 -> 44946 | C638: =Raw_Prices!L15 -> 97.25 | D638: =C638/C637-1 -> 0.038108454 | E638: =IF(_xlfn.XLOOKUP($A638,Firm_Info!$A$2:$A$12,Firm_Info!$C$2:$C$12)="Treated",1,IF(_xlfn.XLOOKUP($A638,Firm_Info!$A$2:$A$12,Firm_Info!$C$2:$C$12)="Control",0,"")) -> 0 | F638: =IFERROR(_xlfn.XLOOKUP($A638,Firm_Info!$A$2:$A$11,Firm_Info!$D$2:$D$11),"") -> 1 | G638: =IF($F638="","",IF($B638>=SUMIFS(Firm_Info!$F$2:$F$11,Firm_Info!$D$2:$D$11,$F638,Firm_Info!$C$2:$C$11,"Treated"),1,0)) -> 0 | H638: =IF($F638="","",$E638*$G638) -> 0 | I638: =IF($F638="","",MOD(ROW()-2,624)-INDEX(Parallel_Trends!$F$5:$F$14,MATCH($A638,Parallel_Trends!$A$5:$A$14,0))) -> -259
... A1249: AMZN | B1249: =Raw_Prices!H626 -> 45838 | C1249: =Raw_Prices!L626 -> 219.39 | D1249: =C1249/C1248-1 -> -0.017510076 | E1249: =IF(_xlfn.XLOOKUP($A1249,Firm_Info!$A$2:$A$12,Firm_Info!$C$2:$C$12)="Treated",1,IF(_xlfn.XLOOKUP($A1249,Firm_Info!$A$2:$A$12,Firm_Info!$C$2:$C$12)="Control",0,"")) -> 0 | F1249: =IFERROR(_xlfn.XLOOKUP($A1249,Firm_Info!$A$2:$A$11,Firm_Info!$D$2:$D$11),"") -> 1 | G1249: =IF($F1249="","",IF($B1249>=SUMIFS(Firm_Info!$F$2:$F$11,Firm_Info!$D$2:$D$11,$F1249,Firm_Info!$C$2:$C$11,"Treated"),1,0)) -> 1 | H1249: =IF($F1249="","",$E1249*$G1249) -> 0 | I1249: =IF($F1249="","",MOD(ROW()-2,624)-INDEX(Parallel_Trends!$F$5:$F$14,MATCH($A1249,Parallel_Trends!$A$5:$A$14,0))) -> 352
A1250: GOOGL | B1250: =Raw_Prices!O3 -> 44929 | C1250: =Raw_Prices!S3 -> 88.798 | E1250: =IF(_xlfn.XLOOKUP($A1250,Firm_Info!$A$2:$A$12,Firm_Info!$C$2:$C$12)="Treated",1,IF(_xlfn.XLOOKUP($A1250,Firm_Info!$A$2:$A$12,Firm_Info!$C$2:$C$12)="Control",0,"")) -> 1 | F1250: =IFERROR(_xlfn.XLOOKUP($A1250,Firm_Info!$A$2:$A$11,Firm_Info!$D$2:$D$11),"") -> 2 | G1250: =IF($F1250="","",IF($B1250>=SUMIFS(Firm_Info!$F$2:$F$11,Firm_Info!$D$2:$D$11,$F1250,Firm_Info!$C$2:$C$11,"Treated"),1,0)) -> 0 | H1250: =IF($F1250="","",$E1250*$G1250) -> 0 | I1250: =IF($F1250="","",MOD(ROW()-2,624)-INDEX(Parallel_Trends!$F$5:$F$14,MATCH($A1250,Parallel_Trends!$A$5:$A$14,0))) -> -329
A1251: GOOGL | B1251: =Raw_Prices!O4 -> 44930 | C1251: =Raw_Prices!S4 -> 87.7618 | D1251: =C1251/C1250-1 -> -0.011669182 | E1251: =IF(_xlfn.XLOOKUP($A1251,Firm_Info!$A$2:$A$12,Firm_Info!$C$2:$C$12)="Treated",1,IF(_xlfn.XLOOKUP($A1251,Firm_Info!$A$2:$A$12,Firm_Info!$C$2:$C$12)="Control",0,"")) -> 1 | F1251: =IFERROR(_xlfn.XLOOKUP($A1251,Firm_Info!$A$2:$A$11,Firm_Info!$D$2:$D$11),"") -> 2 | G1251: =IF($F1251="","",IF($B1251>=SUMIFS(Firm_Info!$F$2:$F$11,Firm_Info!$D$2:$D$11,$F1251,Firm_Info!$C$2:$C$11,"Treated"),1,0)) -> 0 | H1251: =IF($F1251="","",$E1251*$G1251) -> 0 | I1251: =IF($F1251="","",MOD(ROW()-2,624)-INDEX(Parallel_Trends!$F$5:$F$14,MATCH($A1251,Parallel_Trends!$A$5:$A$14,0))) -> -328
A1252: GOOGL | B1252: =Raw_Prices!O5 -> 44931 | C1252: =Raw_Prices!S5 -> 85.8887 | D1252: =C1252/C1251-1 -> -0.021342999 | E1252: =IF(_xlfn.XLOOKUP($A1252,Firm_Info!$A$2:$A$12,Firm_Info!$C$2:$C$12)="Treated",1,IF(_xlfn.XLOOKUP($A1252,Firm_Info!$A$2:$A$12,Firm_Info!$C$2:$C$12)="Control",0,"")) -> 1 | F1252: =IFERROR(_xlfn.XLOOKUP($A1252,Firm_Info!$A$2:$A$11,Firm_Info!$D$2:$D$11),"") -> 2 | G1252: =IF($F1252="","",IF($B1252>=SUMIFS(Firm_Info!$F$2:$F$11,Firm_Info!$D$2:$D$11,$F1252,Firm_Info!$C$2:$C$11,"Treated"),1,0)) -> 0 | H1252: =IF($F1252="","",$E1252*$G1252) -> 0 | I1252: =IF($F1252="","",MOD(ROW()-2,624)-INDEX(Parallel_Trends!$F$5:$F$14,MATCH($A1252,Parallel_Trends!$A$5:$A$14,0))) -> -327
A1253: GOOGL | B1253: =Raw_Prices!O6 -> 44932 | C1253: =Raw_Prices!S6 -> 87.0246 | D1253: =C1253/C1252-1 -> 0.013225255 | E1253: =IF(_xlfn.XLOOKUP($A1253,Firm_Info!$A$2:$A$12,Firm_Info!$C$2:$C$12)="Treated",1,IF(_xlfn.XLOOKUP($A1253,Firm_Info!$A$2:$A$12,Firm_Info!$C$2:$C$12)="Control",0,"")) -> 1 | F1253: =IFERROR(_xlfn.XLOOKUP($A1253,Firm_Info!$A$2:$A$11,Firm_Info!$D$2:$D$11),"") -> 2 | G1253: =IF($F1253="","",IF($B1253>=SUMIFS(Firm_Info!$F$2:$F$11,Firm_Info!$D$2:$D$11,$F1253,Firm_Info!$C$2:$C$11,"Treated"),1,0)) -> 0 | H1253: =IF($F1253="","",$E1253*$G1253) -> 0 | I1253: =IF($F1253="","",MOD(ROW()-2,624)-INDEX(Parallel_Trends!$F$5:$F$14,MATCH($A1253,Parallel_Trends!$A$5:$A$14,0))) -> -326
A1254: GOOGL | B1254: =Raw_Prices!O7 -> 44935 | C1254: =Raw_Prices!S7 -> 87.7021 | D1254: =C1254/C1253-1 -> 0.007785155 | E1254: =IF(_xlfn.XLOOKUP($A1254,Firm_Info!$A$2:$A$12,Firm_Info!$C$2:$C$12)="Treated",1,IF(_xlfn.XLOOKUP($A1254,Firm_Info!$A$2:$A$12,Firm_Info!$C$2:$C$12)="Control",0,"")) -> 1 | F1254: =IFERROR(_xlfn.XLOOKUP($A1254,Firm_Info!$A$2:$A$11,Firm_Info!$D$2:$D$11),"") -> 2 | G1254: =IF($F1254="","",IF($B1254>=SUMIFS(Firm_Info!$F$2:$F$11,Firm_Info!$D$2:$D$11,$F1254,Firm_Info!$C$2:$C$11,"Treated"),1,0)) -> 0 | H1254: =IF($F1254="","",$E1254*$G1254) -> 0 | I1254: =IF($F1254="","",MOD(ROW()-2,624)-INDEX(Parallel_Trends!$F$5:$F$14,MATCH($A1254,Parallel_Trends!$A$5:$A$14,0))) -> -325
A1255: GOOGL | B1255: =Raw_Prices!O8 -> 44936 | C1255: =Raw_Prices!S8 -> 88.1006 | D1255: =C1255/C1254-1 -> 0.0045437909 | E1255: =IF(_xlfn.XLOOKUP($A1255,Firm_Info!$A$2:$A$12,Firm_Info!$C$2:$C$12)="Treated",1,IF(_xlfn.XLOOKUP($A1255,Firm_Info!$A$2:$A$12,Firm_Info!$C$2:$C$12)="Control",0,"")) -> 1 | F1255: =IFERROR(_xlfn.XLOOKUP($A1255,Firm_Info!$A$2:$A$11,Firm_Info!$D$2:$D$11),"") -> 2 | G1255: =IF($F1255="","",IF($B1255>=SUMIFS(Firm_Info!$F$2:$F$11,Firm_Info!$D$2:$D$11,$F1255,Firm_Info!$C$2:$C$11,"Treated"),1,0)) -> 0 | H1255: =IF($F1255="","",$E1255*$G1255) -> 0 | I1255: =IF($F1255="","",MOD(ROW()-2,624)-INDEX(Parallel_Trends!$F$5:$F$14,MATCH($A1255,Parallel_Trends!$A$5:$A$14,0))) -> -324
A1256: GOOGL | B1256: =Raw_Prices!O9 -> 44937 | C1256: =Raw_Prices!S9 -> 91.1895 | D1256: =C1256/C1255-1 -> 0.035061055 | E1256: =IF(_xlfn.XLOOKUP($A1256,Firm_Info!$A$2:$A$12,Firm_Info!$C$2:$C$12)="Treated",1,IF(_xlfn.XLOOKUP($A1256,Firm_Info!$A$2:$A$12,Firm_Info!$C$2:$C$12)="Control",0,"")) -> 1 | F1256: =IFERROR(_xlfn.XLOOKUP($A1256,Firm_Info!$A$2:$A$11,Firm_Info!$D$2:$D$11),"") -> 2 | G1256: =IF($F1256="","",IF($B1256>=SUMIFS(Firm_Info!$F$2:$F$11,Firm_Info!$D$2:$D$11,$F1256,Firm_Info!$C$2:$C$11,"Treated"),1,0)) -> 0 | H1256: =IF($F1256="","",$E1256*$G1256) -> 0 | I1256: =IF($F1256="","",MOD(ROW()-2,624)-INDEX(Parallel_Trends!$F$5:$F$14,MATCH($A1256,Parallel_Trends!$A$5:$A$14,0))) -> -323
A1257: GOOGL | B1257: =Raw_Prices!O10 -> 44938 | C1257: =Raw_Prices!S10 -> 90.8008 | D1257: =C1257/C1256-1 -> -0.0042625522 | E1257: =IF(_xlfn.XLOOKUP($A1257,Firm_Info!$A$2:$A$12,Firm_Info!$C$2:$C$12)="Treated",1,IF(_xlfn.XLOOKUP($A1257,Firm_Info!$A$2:$A$12,Firm_Info!$C$2:$C$12)="Control",0,"")) -> 1 | F1257: =IFERROR(_xlfn.XLOOKUP($A1257,Firm_Info!$A$2:$A$11,Firm_Info!$D$2:$D$11),"") -> 2 | G1257: =IF($F1257="","",IF($B1257>=SUMIFS(Firm_Info!$F$2:$F$11,Firm_Info!$D$2:$D$11,$F1257,Firm_Info!$C$2:$C$11,"Treated"),1,0)) -> 0 | H1257: =IF($F1257="","",$E1257*$G1257) -> 0 | I1257: =IF($F1257="","",MOD(ROW()-2,624)-INDEX(Parallel_Trends!$F$5:$F$14,MATCH($A1257,Parallel_Trends!$A$5:$A$14,0))) -> -322
A1258: GOOGL | B1258: =Raw_Prices!O11 -> 44939 | C1258: =Raw_Prices!S11 -> 91.7873 | D1258: =C1258/C1257-1 -> 0.010864442 | E1258: =IF(_xlfn.XLOOKUP($A1258,Firm_Info!$A$2:$A$12,Firm_Info!$C$2:$C$12)="Treated",1,IF(_xlfn.XLOOKUP($A1258,Firm_Info!$A$2:$A$12,Firm_Info!$C$2:$C$12)="Control",0,"")) -> 1 | F1258: =IFERROR(_xlfn.XLOOKUP($A1258,Firm_Info!$A$2:$A$11,Firm_Info!$D$2:$D$11),"") -> 2 | G1258: =IF($F1258="","",IF($B1258>=SUMIFS(Firm_Info!$F$2:$F$11,Firm_Info!$D$2:$D$11,$F1258,Firm_Info!$C$2:$C$11,"Treated"),1,0)) -> 0 | H1258: =IF($F1258="","",$E1258*$G1258) -> 0 | I1258: =IF($F1258="","",MOD(ROW()-2,624)-INDEX(Parallel_Trends!$F$5:$F$14,MATCH($A1258,Parallel_Trends!$A$5:$A$14,0))) -> -321
A1259: GOOGL | B1259: =Raw_Prices!O12 -> 44943 | C1259: =Raw_Prices!S12 -> 90.9603 | D1259: =C1259/C1258-1 -> -0.0090099611 | E1259: =IF(_xlfn.XLOOKUP($A1259,Firm_Info!$A$2:$A$12,Firm_Info!$C$2:$C$12)="Treated",1,IF(_xlfn.XLOOKUP($A1259,Firm_Info!$A$2:$A$12,Firm_Info!$C$2:$C$12)="Control",0,"")) -> 1 | F1259: =IFERROR(_xlfn.XLOOKUP($A1259,Firm_Info!$A$2:$A$11,Firm_Info!$D$2:$D$11),"") -> 2 | G1259: =IF($F1259="","",IF($B1259>=SUMIFS(Firm_Info!$F$2:$F$11,Firm_Info!$D$2:$D$11,$F1259,Firm_Info!$C$2:$C$11,"Treated"),1,0)) -> 0 | H1259: =IF($F1259="","",$E1259*$G1259) -> 0 | I1259: =IF($F1259="","",MOD(ROW()-2,624)-INDEX(Parallel_Trends!$F$5:$F$14,MATCH($A1259,Parallel_Trends!$A$5:$A$14,0))) -> -320
A1260: GOOGL | B1260: =Raw_Prices!O13 -> 44944 | C1260: =Raw_Prices!S13 -> 90.7908 | D1260: =C1260/C1259-1 -> -0.0018634503 | E1260: =IF(_xlfn.XLOOKUP($A1260,Firm_Info!$A$2:$A$12,Firm_Info!$C$2:$C$12)="Treated",1,IF(_xlfn.XLOOKUP($A1260,Firm_Info!$A$2:$A$12,Firm_Info!$C$2:$C$12)="Control",0,"")) -> 1 | F1260: =IFERROR(_xlfn.XLOOKUP($A1260,Firm_Info!$A$2:$A$11,Firm_Info!$D$2:$D$11),"") -> 2 | G1260: =IF($F1260="","",IF($B1260>=SUMIFS(Firm_Info!$F$2:$F$11,Firm_Info!$D$2:$D$11,$F1260,Firm_Info!$C$2:$C$11,"Treated"),1,0)) -> 0 | H1260: =IF($F1260="","",$E1260*$G1260) -> 0 | I1260: =IF($F1260="","",MOD(ROW()-2,624)-INDEX(Parallel_Trends!$F$5:$F$14,MATCH($A1260,Parallel_Trends!$A$5:$A$14,0))) -> -319
...

Sheet DiD_Regression
A1: DiD Regression — Return ~ Post + Treat + Treat×Post
A3: Term | B3: Coefficient | C3: Std Error | D3: t-stat | E3: p-value | F3: Note
A4: Intercept | B4: =E13 -> 0.0020076508 | C4: =E14 -> 0.00057759556 | D4: =B4/C4 -> 3.4758764 | E4: =_xlfn.T.DIST.2T(ABS(D4),$C$16) -> 0.00051266088
A5: Post | B5: =D13 -> -0.0015592742 | C5: =D14 -> 0.00076473182 | D5: =B5/C5 -> -2.0389818 | E5: =_xlfn.T.DIST.2T(ABS(D5),$C$16) -> 0.041493996
A6: Treat | B6: =C13 -> 0.00049255509 | C6: =C14 -> 0.00081684348 | D6: =B6/C6 -> 0.60299812 | E6: =_xlfn.T.DIST.2T(ABS(D6),$C$16) -> 0.5465319
A7: Treat_x_Post | B7: =B13 -> 0.00019069172 | C7: =B14 -> 0.0010814941 | D7: =B7/C7 -> 0.17632248 | E7: =_xlfn.T.DIST.2T(ABS(D7),$C$16) -> 0.86004634 | F7: DiD Estimate
A10: Raw LINEST output
A11: (coefficients run right-to-left: Treat_x_Post, Treat, Post, Intercept)
B12: Treat_x_Post | C12: Treat | D12: Post | E12: Intercept
A13: Coefficient | B13: {=LINEST(_xlfn.CHOOSECOLS(_xlfn.ANCHORARRAY(A31),1),_xlfn.CHOOSECOLS(_xlfn.ANCHORARRAY(A31),2,3,4),TRUE,TRUE)} -> 0.00019069172 | C13: 0.00049255509 | D13: -0.0015592742 | E13: 0.0020076508
A14: Std Error | B14: 0.0010814941 | C14: 0.00081684348 | D14: 0.00076473182 | E14: 0.00057759556
A15: R² | SE-Y | B15: 0.0013829094 | C15: 0.021127685 | D15: #N/A | E15: #N/A
A16: F | df (resid) | B16: 2.8739725 | C16: 6226 | D16: #N/A | E16: #N/A
A17: SS_reg | SS_resid | B17: 0.0038486434 | C17: 2.779156 | D17: #N/A | E17: #N/A
A19: Model Statistics
A20: R² | B20: =B15 -> 0.0013829094
A21: F-statistic | B21: =B16 -> 2.8739725
A22: Residual df | B22: =C16 -> 6226
A23: Observations (n) | B23: =C16+4 -> 6230
A29: Regression input data — filtered: Ticker ≠ SPY and Return present (FILTER spill)
A30: Return | B30: Post | C30: Treat | D30: Treat_x_Post
A31: {=_xlfn._xlws.FILTER(_xlfn.HSTACK(Panel_Data!D2:D6865,Panel_Data!G2:G6865,Panel_Data!E2:E6865,Panel_Data!H2:H6865),(Panel_Data!A2:A6865<>"SPY")*ISNUMBER(Panel_Data!D2:D6865))} -> 0.021083854 | B31: 0 | C31: 1 | D31: 0
A32: -0.0033759912 | B32: 0 | C32: 1 | D32: 0
A33: 0.024263432 | B33: 0 | C33: 1 | D33: 0
A34: -0.0042301184 | B34: 0 | C34: 1 | D34: 0
A35: 0.027187766 | B35: 0 | C35: 1 | D35: 0
A36: -0.00075193624 | B36: 0 | C36: 1 | D36: 0
A37: 0.028745579 | B37: 0 | C37: 1 | D37: 0
A38: 0.0019749835 | B38: 0 | C38: 1 | D38: 0
A39: -0.011826544 | B39: 0 | C39: 1 | D39: 0
A40: -0.017287234 | B40: 0 | C40: 1 | D40: 0
A41: 0.023530296 | B41: 0 | C41: 1 | D41: 0
A42: 0.023650386 | B42: 0 | C42: 1 | D42: 0
A43: 0.027983067 | B43: 0 | C43: 1 | D43: 0
... A6260: 0.019552585 | B6260: 1 | C6260: 0 | D6260: 0

Sheet Sensitivity
A1: Sensitivity Analysis
A3: Effect of event-window length on the DiD estimate (Treat_x_Post). Window = ± trading days around each firm's own cutoff; SPY excluded.
H4: Live LINEST (cols: Treat_x_Post, Treat, Post, Intercept)
A5: Event Window (± trading days): | B5: 5 | H5: {=LINEST(_xlfn._xlws.FILTER(Panel_Data!$D$2:$D$6241,ISNUMBER(Panel_Data!$D$2:$D$6241)*(ABS(Panel_Data!$I$2:$I$6241)<=$B$5)),_xlfn._xlws.FILTER(_xlfn.HSTACK(Panel_Data!$G$2:$G$6241,Panel_Data!$E$2:$E$6241,Panel_Data!$H$2:$H$6241),ISNUMBER(Panel_Data!$D$2:$D$6241)*(ABS(Panel_Data!$I$2:$I$6241)<=$B$5)),TRUE,TRUE)} -> -0.0032561588 | I5: 0.00495997 | J5: 0.0080393817 | K5: -0.0017812355
A6: DiD Coefficient (Treat_x_Post): | B6: =INDEX(_xlfn.ANCHORARRAY($H$5),1,1) -> -0.0032561588 | H6: 0.01208954 | I6: 0.0089287172 | J6: 0.0085485959 | K6: 0.0063135565
A7: p-value: | B7: =_xlfn.T.DIST.2T(ABS(INDEX(_xlfn.ANCHORARRAY($H$5),1,1)/INDEX(_xlfn.ANCHORARRAY($H$5),2,1)),INDEX(_xlfn.ANCHORARRAY($H$5),4,2)) -> 0.78819405 | H7: 0.013744626 | I7: 0.031567782 | J7: #N/A | K7: #N/A
A8: Observations (n): | B8: =INDEX(_xlfn.ANCHORARRAY($H$5),4,2)+4 -> 110 | H8: 0.49241146 | I8: 106 | J8: #N/A | K8: #N/A
H9: 0.0014721008 | I9: 0.10563164 | J9: #N/A | K9: #N/A
A11: Event Window (±td) | B11: DiD Coef (Treat_x_Post) | C11: p-value | D11: n obs
A12: 1 | B12: {=_xlfn.LET(_xlpm.c,ISNUMBER(Panel_Data!$D$2:$D$6241)*(ABS(Panel_Data!$I$2:$I$6241)<=$A12),_xlpm.arr,LINEST(_xlfn._xlws.FILTER(Panel_Data!$D$2:$D$6241,_xlpm.c),_xlfn._xlws.FILTER(_xlfn.HSTACK(Panel_Data!$G$2:$G$6241,Panel_Data!$E$2:$E$6241,Panel_Data!$H$2:$H$6241),_xlpm.c),TRUE,TRUE),INDEX(_xlpm.arr,1,1))} -> 0.0037405216 | C12: {=_xlfn.LET(_xlpm.c,ISNUMBER(Panel_Data!$D$2:$D$6241)*(ABS(Panel_Data!$I$2:$I$6241)<=$A12),_xlpm.arr,LINEST(_xlfn._xlws.FILTER(Panel_Data!$D$2:$D$6241,_xlpm.c),_xlfn._xlws.FILTER(_xlfn.HSTACK(Panel_Data!$G$2:$G$6241,Panel_Data!$E$2:$E$6241,Panel_Data!$H$2:$H$6241),_xlpm.c),TRUE,TRUE),_xlfn.T.DIST.2T(ABS(INDEX(_xlpm.arr,1,1)/INDEX(_xlpm.arr,2,1)),INDEX(_xlpm.arr,4,2)))} -> 0.92577153 | D12: {=_xlfn.LET(_xlpm.c,ISNUMBER(Panel_Data!$D$2:$D$6241)*(ABS(Panel_Data!$I$2:$I$6241)<=$A12),_xlpm.arr,LINEST(_xlfn._xlws.FILTER(Panel_Data!$D$2:$D$6241,_xlpm.c),_xlfn._xlws.FILTER(_xlfn.HSTACK(Panel_Data!$G$2:$G$6241,Panel_Data!$E$2:$E$6241,Panel_Data!$H$2:$H$6241),_xlpm.c),TRUE,TRUE),INDEX(_xlpm.arr,4,2)+4)} -> 30
A13: 3 | B13: {=_xlfn.LET(_xlpm.c,ISNUMBER(Panel_Data!$D$2:$D$6241)*(ABS(Panel_Data!$I$2:$I$6241)<=$A13),_xlpm.arr,LINEST(_xlfn._xlws.FILTER(Panel_Data!$D$2:$D$6241,_xlpm.c),_xlfn._xlws.FILTER(_xlfn.HSTACK(Panel_Data!$G$2:$G$6241,Panel_Data!$E$2:$E$6241,Panel_Data!$H$2:$H$6241),_xlpm.c),TRUE,TRUE),INDEX(_xlpm.arr,1,1))} -> -0.0081628586 | C13: {=_xlfn.LET(_xlpm.c,ISNUMBER(Panel_Data!$D$2:$D$6241)*(ABS(Panel_Data!$I$2:$I$6241)<=$A13),_xlpm.arr,LINEST(_xlfn._xlws.FILTER(Panel_Data!$D$2:$D$6241,_xlpm.c),_xlfn._xlws.FILTER(_xlfn.HSTACK(Panel_Data!$G$2:$G$6241,Panel_Data!$E$2:$E$6241,Panel_Data!$H$2:$H$6241),_xlpm.c),TRUE,TRUE),_xlfn.T.DIST.2T(ABS(INDEX(_xlpm.arr,1,1)/INDEX(_xlpm.arr,2,1)),INDEX(_xlpm.arr,4,2)))} -> 0.64231855 | D13: {=_xlfn.LET(_xlpm.c,ISNUMBER(Panel_Data!$D$2:$D$6241)*(ABS(Panel_Data!$I$2:$I$6241)<=$A13),_xlpm.arr,LINEST(_xlfn._xlws.FILTER(Panel_Data!$D$2:$D$6241,_xlpm.c),_xlfn._xlws.FILTER(_xlfn.HSTACK(Panel_Data!$G$2:$G$6241,Panel_Data!$E$2:$E$6241,Panel_Data!$H$2:$H$6241),_xlpm.c),TRUE,TRUE),INDEX(_xlpm.arr,4,2)+4)} -> 70
A14: 5 | B14: {=_xlfn.LET(_xlpm.c,ISNUMBER(Panel_Data!$D$2:$D$6241)*(ABS(Panel_Data!$I$2:$I$6241)<=$A14),_xlpm.arr,LINEST(_xlfn._xlws.FILTER(Panel_Data!$D$2:$D$6241,_xlpm.c),_xlfn._xlws.FILTER(_xlfn.HSTACK(Panel_Data!$G$2:$G$6241,Panel_Data!$E$2:$E$6241,Panel_Data!$H$2:$H$6241),_xlpm.c),TRUE,TRUE),INDEX(_xlpm.arr,1,1))} -> -0.0032561588 | C14: {=_xlfn.LET(_xlpm.c,ISNUMBER(Panel_Data!$D$2:$D$6241)*(ABS(Panel_Data!$I$2:$I$6241)<=$A14),_xlpm.arr,LINEST(_xlfn._xlws.FILTER(Panel_Data!$D$2:$D$6241,_xlpm.c),_xlfn._xlws.FILTER(_xlfn.HSTACK(Panel_Data!$G$2:$G$6241,Panel_Data!$E$2:$E$6241,Panel_Data!$H$2:$H$6241),_xlpm.c),TRUE,TRUE),_xlfn.T.DIST.2T(ABS(INDEX(_xlpm.arr,1,1)/INDEX(_xlpm.arr,2,1)),INDEX(_xlpm.arr,4,2)))} -> 0.78819405 | D14: {=_xlfn.LET(_xlpm.c,ISNUMBER(Panel_Data!$D$2:$D$6241)*(ABS(Panel_Data!$I$2:$I$6241)<=$A14),_xlpm.arr,LINEST(_xlfn._xlws.FILTER(Panel_Data!$D$2:$D$6241,_xlpm.c),_xlfn._xlws.FILTER(_xlfn.HSTACK(Panel_Data!$G$2:$G$6241,Panel_Data!$E$2:$E$6241,Panel_Data!$H$2:$H$6241),_xlpm.c),TRUE,TRUE),INDEX(_xlpm.arr,4,2)+4)} -> 110
A15: 10 | B15: {=_xlfn.LET(_xlpm.c,ISNUMBER(Panel_Data!$D$2:$D$6241)*(ABS(Panel_Data!$I$2:$I$6241)<=$A15),_xlpm.arr,LINEST(_xlfn._xlws.FILTER(Panel_Data!$D$2:$D$6241,_xlpm.c),_xlfn._xlws.FILTER(_xlfn.HSTACK(Panel_Data!$G$2:$G$6241,Panel_Data!$E$2:$E$6241,Panel_Data!$H$2:$H$6241),_xlpm.c),TRUE,TRUE),INDEX(_xlpm.arr,1,1))} -> -0.0034697425 | C15: {=_xlfn.LET(_xlpm.c,ISNUMBER(Panel_Data!$D$2:$D$6241)*(ABS(Panel_Data!$I$2:$I$6241)<=$A15),_xlpm.arr,LINEST(_xlfn._xlws.FILTER(Panel_Data!$D$2:$D$6241,_xlpm.c),_xlfn._xlws.FILTER(_xlfn.HSTACK(Panel_Data!$G$2:$G$6241,Panel_Data!$E$2:$E$6241,Panel_Data!$H$2:$H$6241),_xlpm.c),TRUE,TRUE),_xlfn.T.DIST.2T(ABS(INDEX(_xlpm.arr,1,1)/INDEX(_xlpm.arr,2,1)),INDEX(_xlpm.arr,4,2)))} -> 0.61959496 | D15: {=_xlfn.LET(_xlpm.c,ISNUMBER(Panel_Data!$D$2:$D$6241)*(ABS(Panel_Data!$I$2:$I$6241)<=$A15),_xlpm.arr,LINEST(_xlfn._xlws.FILTER(Panel_Data!$D$2:$D$6241,_xlpm.c),_xlfn._xlws.FILTER(_xlfn.HSTACK(Panel_Data!$G$2:$G$6241,Panel_Data!$E$2:$E$6241,Panel_Data!$H$2:$H$6241),_xlpm.c),TRUE,TRUE),INDEX(_xlpm.arr,4,2)+4)} -> 210
A16: 20 | B16: {=_xlfn.LET(_xlpm.c,ISNUMBER(Panel_Data!$D$2:$D$6241)*(ABS(Panel_Data!$I$2:$I$6241)<=$A16),_xlpm.arr,LINEST(_xlfn._xlws.FILTER(Panel_Data!$D$2:$D$6241,_xlpm.c),_xlfn._xlws.FILTER(_xlfn.HSTACK(Panel_Data!$G$2:$G$6241,Panel_Data!$E$2:$E$6241,Panel_Data!$H$2:$H$6241),_xlpm.c),TRUE,TRUE),INDEX(_xlpm.arr,1,1))} -> -0.002710692 | C16: {=_xlfn.LET(_xlpm.c,ISNUMBER(Panel_Data!$D$2:$D$6241)*(ABS(Panel_Data!$I$2:$I$6241)<=$A16),_xlpm.arr,LINEST(_xlfn._xlws.FILTER(Panel_Data!$D$2:$D$6241,_xlpm.c),_xlfn._xlws.FILTER(_xlfn.HSTACK(Panel_Data!$G$2:$G$6241,Panel_Data!$E$2:$E$6241,Panel_Data!$H$2:$H$6241),_xlpm.c),TRUE,TRUE),_xlfn.T.DIST.2T(ABS(INDEX(_xlpm.arr,1,1)/INDEX(_xlpm.arr,2,1)),INDEX(_xlpm.arr,4,2)))} -> 0.50421252 | D16: {=_xlfn.LET(_xlpm.c,ISNUMBER(Panel_Data!$D$2:$D$6241)*(ABS(Panel_Data!$I$2:$I$6241)<=$A16),_xlpm.arr,LINEST(_xlfn._xlws.FILTER(Panel_Data!$D$2:$D$6241,_xlpm.c),_xlfn._xlws.FILTER(_xlfn.HSTACK(Panel_Data!$G$2:$G$6241,Panel_Data!$E$2:$E$6241,Panel_Data!$H$2:$H$6241),_xlpm.c),TRUE,TRUE),INDEX(_xlpm.arr,4,2)+4)} -> 410
A17: 30 | B17: {=_xlfn.LET(_xlpm.c,ISNUMBER(Panel_Data!$D$2:$D$6241)*(ABS(Panel_Data!$I$2:$I$6241)<=$A17),_xlpm.arr,LINEST(_xlfn._xlws.FILTER(Panel_Data!$D$2:$D$6241,_xlpm.c),_xlfn._xlws.FILTER(_xlfn.HSTACK(Panel_Data!$G$2:$G$6241,Panel_Data!$E$2:$E$6241,Panel_Data!$H$2:$H$6241),_xlpm.c),TRUE,TRUE),INDEX(_xlpm.arr,1,1))} -> -0.0026285486 | C17: {=_xlfn.LET(_xlpm.c,ISNUMBER(Panel_Data!$D$2:$D$6241)*(ABS(Panel_Data!$I$2:$I$6241)<=$A17),_xlpm.arr,LINEST(_xlfn._xlws.FILTER(Panel_Data!$D$2:$D$6241,_xlpm.c),_xlfn._xlws.FILTER(_xlfn.HSTACK(Panel_Data!$G$2:$G$6241,Panel_Data!$E$2:$E$6241,Panel_Data!$H$2:$H$6241),_xlpm.c),TRUE,TRUE),_xlfn.T.DIST.2T(ABS(INDEX(_xlpm.arr,1,1)/INDEX(_xlpm.arr,2,1)),INDEX(_xlpm.arr,4,2)))} -> 0.40938886 | D17: {=_xlfn.LET(_xlpm.c,ISNUMBER(Panel_Data!$D$2:$D$6241)*(ABS(Panel_Data!$I$2:$I$6241)<=$A17),_xlpm.arr,LINEST(_xlfn._xlws.FILTER(Panel_Data!$D$2:$D$6241,_xlpm.c),_xlfn._xlws.FILTER(_xlfn.HSTACK(Panel_Data!$G$2:$G$6241,Panel_Data!$E$2:$E$6241,Panel_Data!$H$2:$H$6241),_xlpm.c),TRUE,TRUE),INDEX(_xlpm.arr,4,2)+4)} -> 610
A19: {="DiD across windows: largest |coefficient| at ±"&INDEX($A$12:$A$17,MATCH(MAX(ABS($B$12:$B$17)),ABS($B$12:$B$17),0))&"td. "&IF(ABS(B12)>ABS(B17),"Magnitude is larger at the narrowest (±1) than the widest (±30) window","Magnitude does not increase as the window narrows")&IF(SIGN(B12)<>SIGN(B17)," and even flips sign","")&". "&IF(MIN($C$12:$C$17)<0.05,"At least one window is statistically significant.","All p-values > 0.05 — no significant DiD effect at any window.")} -> DiD across windows: largest |coefficient| at ±3td. Magnitude is larger at the narrowest (±1) than the widest (±30) window and even flips sign. All p-values > 0.05 — no significant DiD effect at any window.

Sheet Summary_Dashboard
A1: Dividend Initiation Announcements: A Difference-in-Differences Analysis
A2: Treated: META · GOOGL · CRM · BKNG · TMUS vs. Matched Controls: AMZN · ADBE · NOW · ABNB · CHTR
A3: Sample: Jan 2023 – Jun 2025 · Daily split-adjusted closes · Event-time difference-in-differences
A5: HEADLINE FINDING | F5: PARALLEL TRENDS CHECK
A6: Pooled DiD estimate (Treat × Post)
A7: Coefficient | B7: =DiD_Regression!B7 -> 0.00019069172
A8: t-stat | B8: =DiD_Regression!D7 -> 0.17632248
A9: p-value | B9: =DiD_Regression!E7 -> 0.86004634
A10: No statistically significant differential return effect detected (p = 0.86).
A12: SENSITIVITY — EVENT WINDOW LENGTH
A13: Window (±td) | B13: DiD Coef | C13: p-value
A14: =Sensitivity!A12 -> 1 | B14: =Sensitivity!B12 -> 0.0037405216 | C14: =Sensitivity!C12 -> 0.92577153
A15: =Sensitivity!A13 -> 3 | B15: =Sensitivity!B13 -> -0.0081628586 | C15: =Sensitivity!C13 -> 0.64231855
A16: =Sensitivity!A14 -> 5 | B16: =Sensitivity!B14 -> -0.0032561588 | C16: =Sensitivity!C14 -> 0.78819405
A17: =Sensitivity!A15 -> 10 | B17: =Sensitivity!B15 -> -0.0034697425 | C17: =Sensitivity!C15 -> 0.61959496
A18: =Sensitivity!A16 -> 20 | B18: =Sensitivity!B16 -> -0.002710692 | C18: =Sensitivity!C16 -> 0.50421252
A19: =Sensitivity!A17 -> 30 | B19: =Sensitivity!B17 -> -0.0026285486 | C19: =Sensitivity!C17 -> 0.40938886
A20: Effect is non-monotonic and insignificant across all event windows tested (±1 to ±30 trading days).
F21: ="Pre-period Treated–Control return correlation: r = "&TEXT(Parallel_Trends!E79,"0.00") -> Pre-period Treated–Control return correlation: r = 0.41
A22: INTERPRETATION
A23: • The DiD design is well-specified — parallel trends roughly hold pre-announcement (Treated–Control return correlation r = 0.41).
A24: • No robust average treatment effect at any event window (±1 to ±30 trading days); every p-value exceeds 0.40.
A25: • Likely driver: a small sample (n = 5 treated firms) with one large outlier — Meta's ~+20% reaction — pulling the group average toward zero, compounded by a broad 2024 mega-cap rally that lifted treated and control firms alike.
A26: • Consistent with recent evidence (e.g., Wolfe Research) that first-time dividend initiators have not reliably outperformed post-announcement — contrasting older event-study literature showing positive average announcement returns.
A28: METHODOLOGY
A29: Data: Stooq daily split-/dividend-adjusted closes. Sample: Jan 3 2023 – Jun 30 2025 (624 trading days × 11 tickers). Specification: Return ~ β0 + β1·Post + β2·Treat + β3·Treat×Post, pooled OLS via LINEST; SPY benchmark excluded (n = 6,230 firm-days). Post defined relative to each pair's treated-firm announcement date.

Sheet Parallel_Trends
A1: Pre-Announcement Parallel Trends Check
A2: Event-time aligned: relative trading day −60…−1 = the last 60 trading days before each firm's own announcement cutoff (≈ 90 calendar days). Group averages taken across the 5 treated and 5 control firms at each relative day.
A4: Firm | B4: Role | C4: Pair | D4: Panel Start Row | E4: Cutoff (Announcement) | F4: Pre-days k (<cutoff)
A5: META | B5: Treated | C5: 1 | D5: 2 | E5: =SUMIFS(Firm_Info!$F$2:$F$11,Firm_Info!$D$2:$D$11,C5,Firm_Info!$C$2:$C$11,"Treated") -> 45323 | F5: =COUNTIF(Raw_Prices!$A$3:$A$626,"<"&E5) -> 271
A6: GOOGL | B6: Treated | C6: 2 | D6: 1250 | E6: =SUMIFS(Firm_Info!$F$2:$F$11,Firm_Info!$D$2:$D$11,C6,Firm_Info!$C$2:$C$11,"Treated") -> 45407 | F6: =COUNTIF(Raw_Prices!$A$3:$A$626,"<"&E6) -> 329
A7: CRM | B7: Treated | C7: 3 | D7: 2498 | E7: =SUMIFS(Firm_Info!$F$2:$F$11,Firm_Info!$D$2:$D$11,C7,Firm_Info!$C$2:$C$11,"Treated") -> 45350 | F7: =COUNTIF(Raw_Prices!$A$3:$A$626,"<"&E7) -> 289
A8: BKNG | B8: Treated | C8: 4 | D8: 3746 | E8: =SUMIFS(Firm_Info!$F$2:$F$11,Firm_Info!$D$2:$D$11,C8,Firm_Info!$C$2:$C$11,"Treated") -> 45344 | F8: =COUNTIF(Raw_Prices!$A$3:$A$626,"<"&E8) -> 285
A9: TMUS | B9: Treated | C9: 5 | D9: 4994 | E9: =SUMIFS(Firm_Info!$F$2:$F$11,Firm_Info!$D$2:$D$11,C9,Firm_Info!$C$2:$C$11,"Treated") -> 45175 | F9: =COUNTIF(Raw_Prices!$A$3:$A$626,"<"&E9) -> 169
A10: AMZN | B10: Control | C10: 1 | D10: 626 | E10: =SUMIFS(Firm_Info!$F$2:$F$11,Firm_Info!$D$2:$D$11,C10,Firm_Info!$C$2:$C$11,"Treated") -> 45323 | F10: =COUNTIF(Raw_Prices!$A$3:$A$626,"<"&E10) -> 271
A11: ADBE | B11: Control | C11: 2 | D11: 1874 | E11: =SUMIFS(Firm_Info!$F$2:$F$11,Firm_Info!$D$2:$D$11,C11,Firm_Info!$C$2:$C$11,"Treated") -> 45407 | F11: =COUNTIF(Raw_Prices!$A$3:$A$626,"<"&E11) -> 329
A12: NOW | B12: Control | C12: 3 | D12: 3122 | E12: =SUMIFS(Firm_Info!$F$2:$F$11,Firm_Info!$D$2:$D$11,C12,Firm_Info!$C$2:$C$11,"Treated") -> 45350 | F12: =COUNTIF(Raw_Prices!$A$3:$A$626,"<"&E12) -> 289
A13: ABNB | B13: Control | C13: 4 | D13: 4370 | E13: =SUMIFS(Firm_Info!$F$2:$F$11,Firm_Info!$D$2:$D$11,C13,Firm_Info!$C$2:$C$11,"Treated") -> 45344 | F13: =COUNTIF(Raw_Prices!$A$3:$A$626,"<"&E13) -> 285
A14: CHTR | B14: Control | C14: 5 | D14: 5618 | E14: =SUMIFS(Firm_Info!$F$2:$F$11,Firm_Info!$D$2:$D$11,C14,Firm_Info!$C$2:$C$11,"Treated") -> 45175 | F14: =COUNTIF(Raw_Prices!$A$3:$A$626,"<"&E14) -> 169
A17: Rel Trading Day | B17: Avg Daily Return — Treated | C17: Avg Daily Return — Control | D17: META | E17: GOOGL | F17: CRM | G17: BKNG | H17: TMUS | I17: AMZN | J17: ADBE | K17: NOW | L17: ABNB | M17: CHTR
A18: -60 | B18: =AVERAGE(D18:H18) -> 0.019114045 | C18: =AVERAGE(I18:M18) -> -0.0035658646 | D18: {=INDEX(Panel_Data!$D:$D,INDEX($D$5:$D$14,MATCH(D$17,$A$5:$A$14,0))+INDEX($F$5:$F$14,MATCH(D$17,$A$5:$A$14,0))+$A18)} -> 0.011998585 | E18: {=INDEX(Panel_Data!$D:$D,INDEX($D$5:$D$14,MATCH(E$17,$A$5:$A$14,0))+INDEX($F$5:$F$14,MATCH(E$17,$A$5:$A$14,0))+$A18)} -> -0.013356782 | F18: {=INDEX(Panel_Data!$D:$D,INDEX($D$5:$D$14,MATCH(F$17,$A$5:$A$14,0))+INDEX($F$5:$F$14,MATCH(F$17,$A$5:$A$14,0))+$A18)} -> 0.093553288 | G18: {=INDEX(Panel_Data!$D:$D,INDEX($D$5:$D$14,MATCH(G$17,$A$5:$A$14,0))+INDEX($F$5:$F$14,MATCH(G$17,$A$5:$A$14,0))+$A18)} -> -0.0046052203 | H18: {=INDEX(Panel_Data!$D:$D,INDEX($D$5:$D$14,MATCH(H$17,$A$5:$A$14,0))+INDEX($F$5:$F$14,MATCH(H$17,$A$5:$A$14,0))+$A18)} -> 0.007980356 | I18: {=INDEX(Panel_Data!$D:$D,INDEX($D$5:$D$14,MATCH(I$17,$A$5:$A$14,0))+INDEX($F$5:$F$14,MATCH(I$17,$A$5:$A$14,0))+$A18)} -> 0.0038386326 | J18: {=INDEX(Panel_Data!$D:$D,INDEX($D$5:$D$14,MATCH(J$17,$A$5:$A$14,0))+INDEX($F$5:$F$14,MATCH(J$17,$A$5:$A$14,0))+$A18)} -> -0.0036018596 | K18: {=INDEX(Panel_Data!$D:$D,INDEX($D$5:$D$14,MATCH(K$17,$A$5:$A$14,0))+INDEX($F$5:$F$14,MATCH(K$17,$A$5:$A$14,0))+$A18)} -> 0.010030489 | ... M18: {=INDEX(Panel_Data!$D:$D,INDEX($D$5:$D$14,MATCH(M$17,$A$5:$A$14,0))+INDEX($F$5:$F$14,MATCH(M$17,$A$5:$A$14,0))+$A18)} -> -0.022904396
A19: =A18+1 -> -59 | B19: =AVERAGE(D19:H19) -> -0.0077137837 | C19: =AVERAGE(I19:M19) -> 0.0050096359 | D19: {=INDEX(Panel_Data!$D:$D,INDEX($D$5:$D$14,MATCH(D$17,$A$5:$A$14,0))+INDEX($F$5:$F$14,MATCH(D$17,$A$5:$A$14,0))+$A19)} -> 0.0038143675 | E19: {=INDEX(Panel_Data!$D:$D,INDEX($D$5:$D$14,MATCH(E$17,$A$5:$A$14,0))+INDEX($F$5:$F$14,MATCH(E$17,$A$5:$A$14,0))+$A19)} -> -0.075003479 | F19: {=INDEX(Panel_Data!$D:$D,INDEX($D$5:$D$14,MATCH(F$17,$A$5:$A$14,0))+INDEX($F$5:$F$14,MATCH(F$17,$A$5:$A$14,0))+$A19)} -> 0.032155617 | G19: {=INDEX(Panel_Data!$D:$D,INDEX($D$5:$D$14,MATCH(G$17,$A$5:$A$14,0))+INDEX($F$5:$F$14,MATCH(G$17,$A$5:$A$14,0))+$A19)} -> 0.0048799228 | H19: {=INDEX(Panel_Data!$D:$D,INDEX($D$5:$D$14,MATCH(H$17,$A$5:$A$14,0))+INDEX($F$5:$F$14,MATCH(H$17,$A$5:$A$14,0))+$A19)} -> -0.0044153471 | I19: {=INDEX(Panel_Data!$D:$D,INDEX($D$5:$D$14,MATCH(I$17,$A$5:$A$14,0))+INDEX($F$5:$F$14,MATCH(I$17,$A$5:$A$14,0))+$A19)} -> 0.0082251082 | J19: {=INDEX(Panel_Data!$D:$D,INDEX($D$5:$D$14,MATCH(J$17,$A$5:$A$14,0))+INDEX($F$5:$F$14,MATCH(J$17,$A$5:$A$14,0))+$A19)} -> -0.016211224 | K19: {=INDEX(Panel_Data!$D:$D,INDEX($D$5:$D$14,MATCH(K$17,$A$5:$A$14,0))+INDEX($F$5:$F$14,MATCH(K$17,$A$5:$A$14,0))+$A19)} -> 0.0073643072 | ... M19: {=INDEX(Panel_Data!$D:$D,INDEX($D$5:$D$14,MATCH(M$17,$A$5:$A$14,0))+INDEX($F$5:$F$14,MATCH(M$17,$A$5:$A$14,0))+$A19)} -> 0.020762299
